> Initialized logger
> /home/annemirasol/remidiv2/serveus/views.py:5: ExtDeprecationWarning: Importing flask.ext.login is deprecated, use flask_login instead.
>   from flask.ext.login import login_user, current_user, LoginManager, logout_user, login_required
> /home/annemirasol/remidiv2/serveus/views.py:7: ExtDeprecationWarning: Importing flask.ext.wtf is deprecated, use flask_wtf instead.
>   from flask.ext.wtf import Form
> Traceback (most recent call last):
>   File "reset.py", line 26, in <module>
> db.session.commit()
>   File "/usr/local/lib/python2.7/dist-packages/sqlalchemy/orm/scoping.py", line 153, in do
> return getattr(self.registry(), name)(*args, **kwargs)
>   File "/usr/local/lib/python2.7/dist-packages/sqlalchemy/orm/session.py", line 943, in commit
> self.transaction.commit()
>   File "/usr/local/lib/python2.7/dist-packages/sqlalchemy/orm/session.py", line 467, in commit
> self._prepare_impl()
>   File "/usr/local/lib/python2.7/dist-packages/sqlalchemy/orm/session.py", line 447, in _prepare_impl
> self.session.flush()
>   File "/usr/local/lib/python2.7/dist-packages/sqlalchemy/orm/session.py", line 2254, in flush
> self._flush(objects)
>   File "/usr/local/lib/python2.7/dist-packages/sqlalchemy/orm/session.py", line 2380, in _flush
> transaction.rollback(_capture_exception=True)
>   File "/usr/local/lib/python2.7/dist-packages/sqlalchemy/util/langhelpers.py", line 66, in __exit__
> compat.reraise(exc_type, exc_value, exc_tb)
>   File "/usr/local/lib/python2.7/dist-packages/sqlalchemy/orm/session.py", line 2344, in _flush
> flush_context.execute()
>   File "/usr/local/lib/python2.7/dist-packages/sqlalchemy/orm/unitofwork.py", line 391, in execute
> rec.execute(self)
>   File "/usr/local/lib/python2.7/dist-packages/sqlalchemy/orm/unitofwork.py", line 556, in execute
> uow
>   File "/usr/local/lib/python2.7/dist-packages/sqlalchemy/orm/persistence.py", line 181, in save_obj
> mapper, table, insert)
>   File "/usr/local/lib/python2.7/dist-packages/sqlalchemy/orm/persistence.py", line 866, in _emit_insert_statements
> execute(statement, params)
>   File "/usr/local/lib/python2.7/dist-packages/sqlalchemy/engine/base.py", line 948, in execute
> return meth(self, multiparams, params)
>   File "/usr/local/lib/python2.7/dist-packages/sqlalchemy/sql/elements.py", line 269, in _execute_on_connection
> return connection._execute_clauseelement(self, multiparams, params)
>   File "/usr/local/lib/python2.7/dist-packages/sqlalchemy/engine/base.py", line 1060, in _execute_clauseelement
> compiled_sql, distilled_params
>   File "/usr/local/lib/python2.7/dist-packages/sqlalchemy/engine/base.py", line 1200, in _execute_context
> context)
>   File "/usr/local/lib/python2.7/dist-packages/sqlalchemy/engine/base.py", line 1413, in _handle_dbapi_exception
> exc_info
>   File "/usr/local/lib/python2.7/dist-packages/sqlalchemy/util/compat.py", line 203, in raise_from_cause
> reraise(type(exception), exception, tb=exc_tb, cause=cause)
>   File "/usr/local/lib/python2.7/dist-packages/sqlalchemy/engine/base.py", line 1193, in _execute_context
> context)
>   File "/usr/local/lib/python2.7/dist-packages/sqlalchemy/engine/default.py", line 507, in do_execute
> cursor.execute(statement, parameters)
> sqlalchemy.exc
> .
> OperationalError
> :
> (sqlite3.OperationalError) no such table: database [SQL: u'INSERT INTO "database" (modified) VALUES (?)'] [parameters: ('2018-03-23 13:56:29.263274',)] (Background on this error at: http://sqlalche.me/e/e3q8)
