> Initialized logger
>  * Debugger is active!
>  * Debugger PIN: 456-115-780
>  * Running on http://0.0.0.0:80/ (Press CTRL+C to quit)
> 192.168.137.21 - - [27/Jan/2019 22:38:13] "POST /api/db/ HTTP/1.1" 200 -
> 192.168.137.21 - - [27/Jan/2019 22:38:47] "POST /api/db/ HTTP/1.1" 200 -
> 192.168.137.21 - - [27/Jan/2019 22:38:53] "POST /api/db/ HTTP/1.1" 200 -
> 192.168.137.21 - - [27/Jan/2019 22:38:53] "POST /api/db/ HTTP/1.1" 200 -
> 192.168.137.21 - - [27/Jan/2019 22:41:30] "POST /api/db/ HTTP/1.1" 200 -
> 192.168.137.21 - - [27/Jan/2019 22:47:21] "POST /api/db/ HTTP/1.1" 200 -
> 192.168.137.21 - - [27/Jan/2019 22:47:26] "POST /api/db/ HTTP/1.1" 200 -
> 192.168.137.21 - - [27/Jan/2019 22:47:27] "POST /api/db/ HTTP/1.1" 200 -
> 192.168.137.21 - - [27/Jan/2019 22:49:54] "POST /api/db/ HTTP/1.1" 200 -
> 192.168.137.21 - - [27/Jan/2019 22:51:45] "POST /api/db/ HTTP/1.1" 200 -
> 192.168.137.21 - - [27/Jan/2019 22:52:03] "POST /api/db/ HTTP/1.1" 200 -
> 192.168.137.21 - - [27/Jan/2019 22:52:14] "POST /api/db/ HTTP/1.1" 200 -
> 192.168.137.21 - - [27/Jan/2019 22:54:05] "POST /api/db/ HTTP/1.1" 200 -
> 192.168.137.21 - - [27/Jan/2019 22:54:40] "POST /api/db/ HTTP/1.1" 200 -
> 192.168.137.21 - - [27/Jan/2019 22:54:42] "POST /api/db/ HTTP/1.1" 200 -
> 127.0.0.1 - - [27/Jan/2019 22:55:44] "GET / HTTP/1.1" 302 -
> Traceback (most recent call last):
>   File "C:\Users\gherz-PC\Anaconda3\envs\py27\lib\SocketServer.py", line 596, in process_request_thread
> 127.0.0.1 - - [27/Jan/2019 22:55:44] "GET / HTTP/1.1" 302 -
>     self.finish_request(request, client_address)
>   File "C:\Users\gherz-PC\Anaconda3\envs\py27\lib\SocketServer.py", line 331, in finish_request
>     self.RequestHandlerClass(request, client_address, self)
>   File "C:\Users\gherz-PC\Anaconda3\envs\py27\lib\SocketServer.py", line 654, in __init__
>     self.finish()
>   File "C:\Users\gherz-PC\Anaconda3\envs\py27\lib\SocketServer.py", line 713, in finish
>     self.wfile.close()
>   File "C:\Users\gherz-PC\Anaconda3\envs\py27\lib\socket.py", line 283, in close
>     self.flush()
>   File "C:\Users\gherz-PC\Anaconda3\envs\py27\lib\socket.py", line 307, in flush
>     self._sock.sendall(view[write_offset:write_offset+buffer_size])
> error: [Errno 10053] An established connection was aborted by the software in your host machine
> 127.0.0.1 - - [27/Jan/2019 22:55:46] "GET /monitoring/1 HTTP/1.1" 301 -
> 127.0.0.1 - - [27/Jan/2019 22:55:48] "GET /monitoring/1/ HTTP/1.1" 200 -
> 127.0.0.1 - - [27/Jan/2019 22:55:53] "GET /static/css/bootstrap-responsive.css HTTP/1.1" 200 -
> 127.0.0.1 - - [27/Jan/2019 22:55:54] "GET /static/css/eyecon-datepicker.css HTTP/1.1" 200 -
> 127.0.0.1 - - [27/Jan/2019 22:55:54] "GET /static/css/bootstrap.min.css HTTP/1.1" 200 -
> 127.0.0.1 - - [27/Jan/2019 22:55:54] "GET /static/images/loading.gif HTTP/1.1" 200 -
> 127.0.0.1 - - [27/Jan/2019 22:55:55] "GET /static/img/glyphicons-halflings.png HTTP/1.1" 200 -
> 127.0.0.1 - - [27/Jan/2019 22:55:55] "GET /static/js/jquery.js HTTP/1.1" 200 -
> 127.0.0.1 - - [27/Jan/2019 22:55:55] "GET /static/js/eyecon-datepicker.js HTTP/1.1" 200 -
> 127.0.0.1 - - [27/Jan/2019 22:55:55] "GET /static/js/bootstrap.min.js HTTP/1.1" 200 -
> 127.0.0.1 - - [27/Jan/2019 22:55:57] "GET /static/images/bar.png HTTP/1.1" 200 -
> 127.0.0.1 - - [27/Jan/2019 22:56:00] "GET /static/img/glyphicons-halflings-white.png HTTP/1.1" 200 -
> 127.0.0.1 - - [27/Jan/2019 22:56:00] "GET /logout/ HTTP/1.1" 302 -
> 127.0.0.1 - - [27/Jan/2019 22:56:04] "GET /index HTTP/1.1" 301 -
> C:\Users\gherz-PC\Desktop\remidiv2\serveus\views.py:83: FlaskWTFDeprecationWarning: "flask_wtf.Form" has been renamed to "FlaskForm" and will be removed in 1.0.
>   return render_template("index.html",login_form = LoginForm(), recovery_form = RecoveryForm())
> C:\Users\gherz-PC\Desktop\remidiv2\serveus\views.py:83: FlaskWTFDeprecationWarning: "flask_wtf.Form" has been renamed to "FlaskForm" and will be removed in 1.0.
>   return render_template("index.html",login_form = LoginForm(), recovery_form = RecoveryForm())
> 127.0.0.1 - - [27/Jan/2019 22:56:05] "GET /index/ HTTP/1.1" 200 -
> 127.0.0.1 - - [27/Jan/2019 22:56:06] "GET /static/js/sha1.js HTTP/1.1" 200 -
> C:\Users\gherz-PC\Desktop\remidiv2\serveus\views.py:824: FlaskWTFDeprecationWarning: "flask_wtf.Form" has been renamed to "FlaskForm" and will be removed in 1.0.
>   form = LoginForm()
> 127.0.0.1 - - [27/Jan/2019 22:56:16] "POST /login/ HTTP/1.1" 302 -
> 127.0.0.1 - - [27/Jan/2019 22:56:16] "GET /monitoring/1 HTTP/1.1" 301 -
> 127.0.0.1 - - [27/Jan/2019 22:56:17] "GET /monitoring/1/ HTTP/1.1" 200 -
> 127.0.0.1 - - [27/Jan/2019 22:56:26] "GET /records/1 HTTP/1.1" 200 -
> 127.0.0.1 - - [27/Jan/2019 22:56:54] "GET /admin/ HTTP/1.1" 200 -
> 127.0.0.1 - - [27/Jan/2019 22:56:54] "GET /static/admin/css/bootstrap2/admin.css HTTP/1.1" 200 -
> 127.0.0.1 - - [27/Jan/2019 22:56:54] "GET /static/bootstrap/bootstrap2/js/bootstrap.min.js HTTP/1.1" 200 -
> 127.0.0.1 - - [27/Jan/2019 22:56:54] "GET /static/bootstrap/bootstrap2/css/bootstrap-responsive.css HTTP/1.1" 200 -
> 127.0.0.1 - - [27/Jan/2019 22:56:54] "GET /static/bootstrap/bootstrap2/css/bootstrap.css HTTP/1.1" 200 -
> 127.0.0.1 - - [27/Jan/2019 22:56:55] "GET /static/vendor/moment-2.8.4.min.js HTTP/1.1" 200 -
> 127.0.0.1 - - [27/Jan/2019 22:56:55] "GET /static/vendor/select2/select2.min.js HTTP/1.1" 200 -
> 127.0.0.1 - - [27/Jan/2019 22:56:55] "GET /static/vendor/jquery-2.1.1.min.js HTTP/1.1" 200 -
> 127.0.0.1 - - [27/Jan/2019 22:56:56] "GET /favicon.ico HTTP/1.1" 404 -
> 127.0.0.1 - - [27/Jan/2019 22:57:06] "GET /admin/user/ HTTP/1.1" 200 -
> 127.0.0.1 - - [27/Jan/2019 22:57:06] "GET /static/vendor/select2/select2.css HTTP/1.1" 200 -
> 127.0.0.1 - - [27/Jan/2019 22:57:07] "GET /static/vendor/bootstrap-daterangepicker/daterangepicker-bs2.css HTTP/1.1" 200 -
> 127.0.0.1 - - [27/Jan/2019 22:57:07] "GET /static/admin/js/filters-1.0.0.js HTTP/1.1" 200 -
> 127.0.0.1 - - [27/Jan/2019 22:57:07] "GET /static/admin/js/actions-1.0.0.js HTTP/1.1" 200 -
> 127.0.0.1 - - [27/Jan/2019 22:57:07] "GET /static/admin/js/form-1.0.0.js HTTP/1.1" 200 -
> 127.0.0.1 - - [27/Jan/2019 22:57:07] "GET /static/vendor/bootstrap-daterangepicker/daterangepicker.js HTTP/1.1" 200 -
> 127.0.0.1 - - [27/Jan/2019 22:57:08] "GET /static/bootstrap/bootstrap2/img/glyphicons-halflings.png HTTP/1.1" 200 -
> 127.0.0.1 - - [27/Jan/2019 22:57:10] "GET /admin/user/new/?url=%2Fadmin%2Fuser%2F HTTP/1.1" 200 -
> 127.0.0.1 - - [27/Jan/2019 22:57:12] "GET /static/vendor/select2/select2.png HTTP/1.1" 200 -
> 127.0.0.1 - - [27/Jan/2019 22:57:30] "GET /static/vendor/select2/select2-spinner.gif HTTP/1.1" 200 -
> 127.0.0.1 - - [27/Jan/2019 22:57:41] "POST /admin/user/new/?url=%2Fadmin%2Fuser%2F HTTP/1.1" 500 -
> Traceback (most recent call last):
>   File "C:\Users\gherz-PC\Anaconda3\envs\py27\lib\site-packages\flask\app.py", line 2309, in __call__
>     return self.wsgi_app(environ, start_response)
>   File "C:\Users\gherz-PC\Anaconda3\envs\py27\lib\site-packages\flask\app.py", line 2295, in wsgi_app
>     response = self.handle_exception(e)
>   File "C:\Users\gherz-PC\Anaconda3\envs\py27\lib\site-packages\flask\app.py", line 1741, in handle_exception
>     reraise(exc_type, exc_value, tb)
>   File "C:\Users\gherz-PC\Anaconda3\envs\py27\lib\site-packages\flask\app.py", line 2292, in wsgi_app
>     response = self.full_dispatch_request()
>   File "C:\Users\gherz-PC\Anaconda3\envs\py27\lib\site-packages\flask\app.py", line 1815, in full_dispatch_request
>     rv = self.handle_user_exception(e)
>   File "C:\Users\gherz-PC\Anaconda3\envs\py27\lib\site-packages\flask\app.py", line 1718, in handle_user_exception
>     reraise(exc_type, exc_value, tb)
>   File "C:\Users\gherz-PC\Anaconda3\envs\py27\lib\site-packages\flask\app.py", line 1813, in full_dispatch_request
>     rv = self.dispatch_request()
>   File "C:\Users\gherz-PC\Anaconda3\envs\py27\lib\site-packages\flask\app.py", line 1799, in dispatch_request
>     return self.view_functions[rule.endpoint](**req.view_args)
>   File "C:\Users\gherz-PC\Anaconda3\envs\py27\lib\site-packages\flask_admin\base.py", line 69, in inner
>     return self._run_view(f, *args, **kwargs)
>   File "C:\Users\gherz-PC\Anaconda3\envs\py27\lib\site-packages\flask_admin\base.py", line 368, in _run_view
>     return fn(self, *args, **kwargs)
>   File "C:\Users\gherz-PC\Anaconda3\envs\py27\lib\site-packages\flask_admin\model\base.py", line 2048, in create_view
>     model = self.create_model(form)
>   File "C:\Users\gherz-PC\Anaconda3\envs\py27\lib\site-packages\flask_admin\contrib\sqla\view.py", line 1085, in create_model
>     if not self.handle_view_exception(ex):
>   File "C:\Users\gherz-PC\Anaconda3\envs\py27\lib\site-packages\flask_admin\contrib\sqla\view.py", line 1068, in handle_view_exception
>     return super(ModelView, self).handle_view_exception(exc)
>   File "C:\Users\gherz-PC\Anaconda3\envs\py27\lib\site-packages\flask_admin\contrib\sqla\view.py", line 1082, in create_model
>     self._on_model_change(form, model, True)
>   File "C:\Users\gherz-PC\Anaconda3\envs\py27\lib\site-packages\flask_admin\model\base.py", line 1548, in _on_model_change
>     self.on_model_change(form, model, is_created)
> TypeError: on_model_change() takes exactly 3 arguments (4 given)
> 127.0.0.1 - - [27/Jan/2019 22:57:41] "GET /admin/user/new/?__debugger__=yes&cmd=resource&f=style.css HTTP/1.1" 200 -
> 127.0.0.1 - - [27/Jan/2019 22:57:42] "GET /admin/user/new/?__debugger__=yes&cmd=resource&f=debugger.js HTTP/1.1" 200 -
> 127.0.0.1 - - [27/Jan/2019 22:57:42] "GET /admin/user/new/?__debugger__=yes&cmd=resource&f=jquery.js HTTP/1.1" 200 -
> 127.0.0.1 - - [27/Jan/2019 22:57:43] "GET /admin/user/new/?__debugger__=yes&cmd=resource&f=ubuntu.ttf HTTP/1.1" 200 -
> 127.0.0.1 - - [27/Jan/2019 22:57:44] "GET /admin/user/new/?__debugger__=yes&cmd=resource&f=console.png HTTP/1.1" 200 -
> 127.0.0.1 - - [27/Jan/2019 22:57:45] "GET /admin/user/new/?__debugger__=yes&cmd=resource&f=console.png HTTP/1.1" 200 -
> 127.0.0.1 - - [27/Jan/2019 22:59:03] "POST /admin/user/new/?url=%2Fadmin%2Fuser%2F HTTP/1.1" 500 -
> Traceback (most recent call last):
>   File "C:\Users\gherz-PC\Anaconda3\envs\py27\lib\site-packages\flask\app.py", line 2309, in __call__
>     return self.wsgi_app(environ, start_response)
>   File "C:\Users\gherz-PC\Anaconda3\envs\py27\lib\site-packages\flask\app.py", line 2295, in wsgi_app
>     response = self.handle_exception(e)
>   File "C:\Users\gherz-PC\Anaconda3\envs\py27\lib\site-packages\flask\app.py", line 1741, in handle_exception
>     reraise(exc_type, exc_value, tb)
>   File "C:\Users\gherz-PC\Anaconda3\envs\py27\lib\site-packages\flask\app.py", line 2292, in wsgi_app
>     response = self.full_dispatch_request()
>   File "C:\Users\gherz-PC\Anaconda3\envs\py27\lib\site-packages\flask\app.py", line 1815, in full_dispatch_request
>     rv = self.handle_user_exception(e)
>   File "C:\Users\gherz-PC\Anaconda3\envs\py27\lib\site-packages\flask\app.py", line 1718, in handle_user_exception
>     reraise(exc_type, exc_value, tb)
>   File "C:\Users\gherz-PC\Anaconda3\envs\py27\lib\site-packages\flask\app.py", line 1813, in full_dispatch_request
>     rv = self.dispatch_request()
> 127.0.0.1 - - [27/Jan/2019 22:59:03] "GET /admin/user/new/?__debugger__=yes&cmd=resource&f=style.css HTTP/1.1" 200 -
> 127.0.0.1 - - [27/Jan/2019 22:59:03] "GET /admin/user/new/?__debugger__=yes&cmd=resource&f=jquery.js HTTP/1.1" 200 -
>   File "C:\Users\gherz-PC\Anaconda3\envs\py27\lib\site-packages\flask\app.py", line 1799, in dispatch_request
>     return self.view_functions[rule.endpoint](**req.view_args)
>   File "C:\Users\gherz-PC\Anaconda3\envs\py27\lib\site-packages\flask_admin\base.py", line 69, in inner
>     return self._run_view(f, *args, **kwargs)
>   File "C:\Users\gherz-PC\Anaconda3\envs\py27\lib\site-packages\flask_admin\base.py", line 368, in _run_view
>     return fn(self, *args, **kwargs)
>   File "C:\Users\gherz-PC\Anaconda3\envs\py27\lib\site-packages\flask_admin\model\base.py", line 2048, in create_view
>     model = self.create_model(form)
>   File "C:\Users\gherz-PC\Anaconda3\envs\py27\lib\site-packages\flask_admin\contrib\sqla\view.py", line 1085, in create_model
>     if not self.handle_view_exception(ex):
>   File "C:\Users\gherz-PC\Anaconda3\envs\py27\lib\site-packages\flask_admin\contrib\sqla\view.py", line 1068, in handle_view_exception
>     return super(ModelView, self).handle_view_exception(exc)
>   File "C:\Users\gherz-PC\Anaconda3\envs\py27\lib\site-packages\flask_admin\contrib\sqla\view.py", line 1080, in create_model
>     form.populate_obj(model)
>   File "C:\Users\gherz-PC\Anaconda3\envs\py27\lib\site-packages\wtforms\form.py", line 96, in populate_obj
>     field.populate_obj(obj, name)
>   File "C:\Users\gherz-PC\Anaconda3\envs\py27\lib\site-packages\wtforms\fields\core.py", line 330, in populate_obj
>     setattr(obj, name, self.data)
>   File "C:\Users\gherz-PC\Anaconda3\envs\py27\lib\site-packages\sqlalchemy\orm\attributes.py", line 229, in __set__
>     instance_dict(instance), value, None)
>   File "C:\Users\gherz-PC\Anaconda3\envs\py27\lib\site-packages\sqlalchemy\orm\attributes.py", line 710, in set
>     value, old, initiator)
>   File "C:\Users\gherz-PC\Anaconda3\envs\py27\lib\site-packages\sqlalchemy\orm\attributes.py", line 717, in fire_replace_event
>     state, value, previous, initiator or self._replace_token)
>   File "C:\Users\gherz-PC\Anaconda3\envs\py27\lib\site-packages\sqlalchemy\orm\util.py", line 136, in set_
>     return validator(state.obj(), key, value)
>   File "C:\Users\gherz-PC\Desktop\remidiv2\serveus\models.py", line 80, in update_password
>     Database.query.first().modified = datetime.datetime.now()
>   File "C:\Users\gherz-PC\Anaconda3\envs\py27\lib\site-packages\sqlalchemy\orm\query.py", line 2895, in first
>     ret = list(self[0:1])
>   File "C:\Users\gherz-PC\Anaconda3\envs\py27\lib\site-packages\sqlalchemy\orm\query.py", line 2687, in __getitem__
>     return list(res)
>   File "C:\Users\gherz-PC\Anaconda3\envs\py27\lib\site-packages\sqlalchemy\orm\query.py", line 2994, in __iter__
>     self.session._autoflush()
>   File "C:\Users\gherz-PC\Anaconda3\envs\py27\lib\site-packages\sqlalchemy\orm\session.py", line 1444, in _autoflush
>     util.raise_from_cause(e)
>   File "C:\Users\gherz-PC\Anaconda3\envs\py27\lib\site-packages\sqlalchemy\util\compat.py", line 265, in raise_from_cause
>     reraise(type(exception), exception, tb=exc_tb, cause=cause)
>   File "C:\Users\gherz-PC\Anaconda3\envs\py27\lib\site-packages\sqlalchemy\orm\session.py", line 1434, in _autoflush
>     self.flush()
>   File "C:\Users\gherz-PC\Anaconda3\envs\py27\lib\site-packages\sqlalchemy\orm\session.py", line 2254, in flush
>     self._flush(objects)
>   File "C:\Users\gherz-PC\Anaconda3\envs\py27\lib\site-packages\sqlalchemy\orm\session.py", line 2380, in _flush
>     transaction.rollback(_capture_exception=True)
>   File "C:\Users\gherz-PC\Anaconda3\envs\py27\lib\site-packages\sqlalchemy\util\langhelpers.py", line 66, in __exit__
>     compat.reraise(exc_type, exc_value, exc_tb)
>   File "C:\Users\gherz-PC\Anaconda3\envs\py27\lib\site-packages\sqlalchemy\orm\session.py", line 2344, in _flush
>     flush_context.execute()
>   File "C:\Users\gherz-PC\Anaconda3\envs\py27\lib\site-packages\sqlalchemy\orm\unitofwork.py", line 391, in execute
>     rec.execute(self)
>   File "C:\Users\gherz-PC\Anaconda3\envs\py27\lib\site-packages\sqlalchemy\orm\unitofwork.py", line 556, in execute
>     uow
>   File "C:\Users\gherz-PC\Anaconda3\envs\py27\lib\site-packages\sqlalchemy\orm\persistence.py", line 177, in save_obj
>     mapper, table, update)
>   File "C:\Users\gherz-PC\Anaconda3\envs\py27\lib\site-packages\sqlalchemy\orm\persistence.py", line 768, in _emit_update_statements
>     execute(statement, multiparams)
>   File "C:\Users\gherz-PC\Anaconda3\envs\py27\lib\site-packages\sqlalchemy\engine\base.py", line 948, in execute
>     return meth(self, multiparams, params)
>   File "C:\Users\gherz-PC\Anaconda3\envs\py27\lib\site-packages\sqlalchemy\sql\elements.py", line 269, in _execute_on_connection
>     return connection._execute_clauseelement(self, multiparams, params)
>   File "C:\Users\gherz-PC\Anaconda3\envs\py27\lib\site-packages\sqlalchemy\engine\base.py", line 1060, in _execute_clauseelement
>     compiled_sql, distilled_params
>   File "C:\Users\gherz-PC\Anaconda3\envs\py27\lib\site-packages\sqlalchemy\engine\base.py", line 1200, in _execute_context
>     context)
>   File "C:\Users\gherz-PC\Anaconda3\envs\py27\lib\site-packages\sqlalchemy\engine\base.py", line 1413, in _handle_dbapi_exception
>     exc_info
>   File "C:\Users\gherz-PC\Anaconda3\envs\py27\lib\site-packages\sqlalchemy\util\compat.py", line 265, in raise_from_cause
>     reraise(type(exception), exception, tb=exc_tb, cause=cause)
>   File "C:\Users\gherz-PC\Anaconda3\envs\py27\lib\site-packages\sqlalchemy\engine\base.py", line 1193, in _execute_context
>     context)
>   File "C:\Users\gherz-PC\Anaconda3\envs\py27\lib\site-packages\sqlalchemy\engine\default.py", line 509, in do_execute
>     cursor.execute(statement, parameters)
> OperationalError: (raised as a result of Query-invoked autoflush; consider using a session.no_autoflush block if this flush is occurring prematurely) (sqlite3.OperationalError) database is locked [SQL: u'UPDATE "database" SET modified=? WHERE "database".id = ?'] [parameters: ('2019-01-27 22:58:57.161000', 1)] (Background on this error at: http://sqlalche.me/e/e3q8)
> 127.0.0.1 - - [27/Jan/2019 22:59:03] "GET /admin/user/new/?__debugger__=yes&cmd=resource&f=debugger.js HTTP/1.1" 200 -
> 127.0.0.1 - - [27/Jan/2019 22:59:04] "GET /admin/user/new/?__debugger__=yes&cmd=resource&f=console.png HTTP/1.1" 200 -
> 127.0.0.1 - - [27/Jan/2019 22:59:04] "GET /admin/user/new/?__debugger__=yes&cmd=resource&f=ubuntu.ttf HTTP/1.1" 200 -
> 127.0.0.1 - - [27/Jan/2019 22:59:04] "GET /admin/user/new/?__debugger__=yes&cmd=resource&f=console.png HTTP/1.1" 200 -
> 127.0.0.1 - - [27/Jan/2019 22:59:30] "POST /admin/user/new/?url=%2Fadmin%2Fuser%2F HTTP/1.1" 500 -
> Traceback (most recent call last):
>   File "C:\Users\gherz-PC\Anaconda3\envs\py27\lib\site-packages\flask\app.py", line 2309, in __call__
>     return self.wsgi_app(environ, start_response)
>   File "C:\Users\gherz-PC\Anaconda3\envs\py27\lib\site-packages\flask\app.py", line 2295, in wsgi_app
>     response = self.handle_exception(e)
>   File "C:\Users\gherz-PC\Anaconda3\envs\py27\lib\site-packages\flask\app.py", line 1741, in handle_exception
>     reraise(exc_type, exc_value, tb)
>   File "C:\Users\gherz-PC\Anaconda3\envs\py27\lib\site-packages\flask\app.py", line 2292, in wsgi_app
>     response = self.full_dispatch_request()
>   File "C:\Users\gherz-PC\Anaconda3\envs\py27\lib\site-packages\flask\app.py", line 1815, in full_dispatch_request
>     rv = self.handle_user_exception(e)
>   File "C:\Users\gherz-PC\Anaconda3\envs\py27\lib\site-packages\flask\app.py", line 1718, in handle_user_exception
>     reraise(exc_type, exc_value, tb)
>   File "C:\Users\gherz-PC\Anaconda3\envs\py27\lib\site-packages\flask\app.py", line 1813, in full_dispatch_request
>     rv = self.dispatch_request()
>   File "C:\Users\gherz-PC\Anaconda3\envs\py27\lib\site-packages\flask\app.py", line 1799, in dispatch_request
>     return self.view_functions[rule.endpoint](**req.view_args)
>   File "C:\Users\gherz-PC\Anaconda3\envs\py27\lib\site-packages\flask_admin\base.py", line 69, in inner
>     return self._run_view(f, *args, **kwargs)
>   File "C:\Users\gherz-PC\Anaconda3\envs\py27\lib\site-packages\flask_admin\base.py", line 368, in _run_view
>     return fn(self, *args, **kwargs)
>   File "C:\Users\gherz-PC\Anaconda3\envs\py27\lib\site-packages\flask_admin\model\base.py", line 2048, in create_view
>     model = self.create_model(form)
>   File "C:\Users\gherz-PC\Anaconda3\envs\py27\lib\site-packages\flask_admin\contrib\sqla\view.py", line 1085, in create_model
>     if not self.handle_view_exception(ex):
>   File "C:\Users\gherz-PC\Anaconda3\envs\py27\lib\site-packages\flask_admin\contrib\sqla\view.py", line 1068, in handle_view_exception
>     return super(ModelView, self).handle_view_exception(exc)
>   File "C:\Users\gherz-PC\Anaconda3\envs\py27\lib\site-packages\flask_admin\contrib\sqla\view.py", line 1080, in create_model
>     form.populate_obj(model)
>   File "C:\Users\gherz-PC\Anaconda3\envs\py27\lib\site-packages\wtforms\form.py", line 96, in populate_obj
>     field.populate_obj(obj, name)
>   File "C:\Users\gherz-PC\Anaconda3\envs\py27\lib\site-packages\wtforms\fields\core.py", line 330, in populate_obj
>     setattr(obj, name, self.data)
>   File "C:\Users\gherz-PC\Anaconda3\envs\py27\lib\site-packages\sqlalchemy\orm\attributes.py", line 229, in __set__
>     instance_dict(instance), value, None)
>   File "C:\Users\gherz-PC\Anaconda3\envs\py27\lib\site-packages\sqlalchemy\orm\attributes.py", line 710, in set
>     value, old, initiator)
>   File "C:\Users\gherz-PC\Anaconda3\envs\py27\lib\site-packages\sqlalchemy\orm\attributes.py", line 717, in fire_replace_event
>     state, value, previous, initiator or self._replace_token)
>   File "C:\Users\gherz-PC\Anaconda3\envs\py27\lib\site-packages\sqlalchemy\orm\util.py", line 136, in set_
>     return validator(state.obj(), key, value)
>   File "C:\Users\gherz-PC\Desktop\remidiv2\serveus\models.py", line 80, in update_password
>     Database.query.first().modified = datetime.datetime.now()
>   File "C:\Users\gherz-PC\Anaconda3\envs\py27\lib\site-packages\sqlalchemy\orm\query.py", line 2895, in first
>     ret = list(self[0:1])
>   File "C:\Users\gherz-PC\Anaconda3\envs\py27\lib\site-packages\sqlalchemy\orm\query.py", line 2687, in __getitem__
>     return list(res)
>   File "C:\Users\gherz-PC\Anaconda3\envs\py27\lib\site-packages\sqlalchemy\orm\query.py", line 2994, in __iter__
>     self.session._autoflush()
>   File "C:\Users\gherz-PC\Anaconda3\envs\py27\lib\site-packages\sqlalchemy\orm\session.py", line 1444, in _autoflush
>     util.raise_from_cause(e)
>   File "C:\Users\gherz-PC\Anaconda3\envs\py27\lib\site-packages\sqlalchemy\util\compat.py", line 265, in raise_from_cause
>     reraise(type(exception), exception, tb=exc_tb, cause=cause)
>   File "C:\Users\gherz-PC\Anaconda3\envs\py27\lib\site-packages\sqlalchemy\orm\session.py", line 1434, in _autoflush
>     self.flush()
>   File "C:\Users\gherz-PC\Anaconda3\envs\py27\lib\site-packages\sqlalchemy\orm\session.py", line 2254, in flush
>     self._flush(objects)
>   File "C:\Users\gherz-PC\Anaconda3\envs\py27\lib\site-packages\sqlalchemy\orm\session.py", line 2380, in _flush
>     transaction.rollback(_capture_exception=True)
>   File "C:\Users\gherz-PC\Anaconda3\envs\py27\lib\site-packages\sqlalchemy\util\langhelpers.py", line 66, in __exit__
>     compat.reraise(exc_type, exc_value, exc_tb)
>   File "C:\Users\gherz-PC\Anaconda3\envs\py27\lib\site-packages\sqlalchemy\orm\session.py", line 2344, in _flush
>     flush_context.execute()
>   File "C:\Users\gherz-PC\Anaconda3\envs\py27\lib\site-packages\sqlalchemy\orm\unitofwork.py", line 391, in execute
>     rec.execute(self)
>   File "C:\Users\gherz-PC\Anaconda3\envs\py27\lib\site-packages\sqlalchemy\orm\unitofwork.py", line 556, in execute
>     uow
>   File "C:\Users\gherz-PC\Anaconda3\envs\py27\lib\site-packages\sqlalchemy\orm\persistence.py", line 177, in save_obj
>     mapper, table, update)
>   File "C:\Users\gherz-PC\Anaconda3\envs\py27\lib\site-packages\sqlalchemy\orm\persistence.py", line 768, in _emit_update_statements
>     execute(statement, multiparams)
>   File "C:\Users\gherz-PC\Anaconda3\envs\py27\lib\site-packages\sqlalchemy\engine\base.py", line 948, in execute
>     return meth(self, multiparams, params)
>   File "C:\Users\gherz-PC\Anaconda3\envs\py27\lib\site-packages\sqlalchemy\sql\elements.py", line 269, in _execute_on_connection
>     return connection._execute_clauseelement(self, multiparams, params)
>   File "C:\Users\gherz-PC\Anaconda3\envs\py27\lib\site-packages\sqlalchemy\engine\base.py", line 1060, in _execute_clauseelement
>     compiled_sql, distilled_params
>   File "C:\Users\gherz-PC\Anaconda3\envs\py27\lib\site-packages\sqlalchemy\engine\base.py", line 1200, in _execute_context
>     context)
>   File "C:\Users\gherz-PC\Anaconda3\envs\py27\lib\site-packages\sqlalchemy\engine\base.py", line 1413, in _handle_dbapi_exception
>     exc_info
>   File "C:\Users\gherz-PC\Anaconda3\envs\py27\lib\site-packages\sqlalchemy\util\compat.py", line 265, in raise_from_cause
>     reraise(type(exception), exception, tb=exc_tb, cause=cause)
>   File "C:\Users\gherz-PC\Anaconda3\envs\py27\lib\site-packages\sqlalchemy\engine\base.py", line 1193, in _execute_context
>     context)
>   File "C:\Users\gherz-PC\Anaconda3\envs\py27\lib\site-packages\sqlalchemy\engine\default.py", line 509, in do_execute
>     cursor.execute(statement, parameters)
> OperationalError: (raised as a result of Query-invoked autoflush; consider using a session.no_autoflush block if this flush is occurring prematurely) (sqlite3.OperationalError) database is locked [SQL: u'UPDATE "database" SET modified=? WHERE "database".id = ?'] [parameters: ('2019-01-27 22:59:24.943000', 1)] (Background on this error at: http://sqlalche.me/e/e3q8)
> 127.0.0.1 - - [27/Jan/2019 22:59:30] "GET /admin/user/new/?__debugger__=yes&cmd=resource&f=style.css HTTP/1.1" 200 -
> 127.0.0.1 - - [27/Jan/2019 22:59:30] "GET /admin/user/new/?__debugger__=yes&cmd=resource&f=jquery.js HTTP/1.1" 200 -
> 127.0.0.1 - - [27/Jan/2019 22:59:30] "GET /admin/user/new/?__debugger__=yes&cmd=resource&f=debugger.js HTTP/1.1" 200 -
> 127.0.0.1 - - [27/Jan/2019 22:59:30] "GET /admin/user/new/?__debugger__=yes&cmd=resource&f=console.png HTTP/1.1" 200 -
> 127.0.0.1 - - [27/Jan/2019 22:59:31] "GET /admin/user/new/?__debugger__=yes&cmd=resource&f=ubuntu.ttf HTTP/1.1" 200 -
> 127.0.0.1 - - [27/Jan/2019 22:59:31] "GET /admin/user/new/?__debugger__=yes&cmd=resource&f=console.png HTTP/1.1" 200 -
