> Initialized logger
> /home/annemirasol/remidiv2/serveus/views.py:5: ExtDeprecationWarning: Importing flask.ext.login is deprecated, use flask_login instead.
>   from flask.ext.login import login_user, current_user, LoginManager, logout_user, login_required
> /home/annemirasol/remidiv2/serveus/forms.py:2: ExtDeprecationWarning: Importing flask.ext.wtf is deprecated, use flask_wtf instead.
>   from flask.ext.wtf import Form
>  * Running on http://0.0.0.0:80/ (Press CTRL+C to quit)
>  * Restarting with stat
> Initialized logger
> /home/annemirasol/remidiv2/serveus/views.py:5: ExtDeprecationWarning: Importing flask.ext.login is deprecated, use flask_login instead.
>   from flask.ext.login import login_user, current_user, LoginManager, logout_user, login_required
> /home/annemirasol/remidiv2/serveus/forms.py:2: ExtDeprecationWarning: Importing flask.ext.wtf is deprecated, use flask_wtf instead.
>   from flask.ext.wtf import Form
>  * Debugger is active!
>  * Debugger PIN: 322-981-763
> 127.0.0.1 - - [12/Jun/2018 20:09:38] "[37mGET /static/favicon.ico HTTP/1.1[0m" 200 -
> 127.0.0.1 - - [12/Jun/2018 20:09:41] "[37mGET /static/js/markerwithlabel.js HTTP/1.1[0m" 200 -
> 127.0.0.1 - - [12/Jun/2018 20:09:41] "[37mGET /static/img/glyphicons-halflings.png HTTP/1.1[0m" 200 -
> Error on request:
Traceback (most recent call last):
  File "/usr/local/lib/python2.7/dist-packages/werkzeug/serving.py", line 270, in run_wsgi
    execute(self.server.app)
  File "/usr/local/lib/python2.7/dist-packages/werkzeug/serving.py", line 261, in execute
    write(data)
  File "/usr/local/lib/python2.7/dist-packages/werkzeug/serving.py", line 227, in write
    self.send_header(key, value)
  File "/usr/lib/python2.7/BaseHTTPServer.py", line 412, in send_header
    self.wfile.write("%s: %s\r\n" % (keyword, value))
IOError: [Errno 32] Broken pipe
> 127.0.0.1 - - [12/Jun/2018 20:09:46] "[37mGET /monitoring/1/ HTTP/1.1[0m" 200 -
> 127.0.0.1 - - [12/Jun/2018 20:09:46] "[36mGET /static/css/bootstrap.min.css HTTP/1.1[0m" 304 -
> 127.0.0.1 - - [12/Jun/2018 20:09:46] "[36mGET /static/css/bootstrap-responsive.css HTTP/1.1[0m" 304 -
> 127.0.0.1 - - [12/Jun/2018 20:09:46] "[36mGET /static/css/eyecon-datepicker.css HTTP/1.1[0m" 304 -
> 127.0.0.1 - - [12/Jun/2018 20:09:46] "[36mGET /static/js/jquery.js HTTP/1.1[0m" 304 -
> 127.0.0.1 - - [12/Jun/2018 20:09:46] "[36mGET /static/js/bootstrap.min.js HTTP/1.1[0m" 304 -
> 127.0.0.1 - - [12/Jun/2018 20:09:46] "[36mGET /static/js/eyecon-datepicker.js HTTP/1.1[0m" 304 -
> 127.0.0.1 - - [12/Jun/2018 20:09:46] "[36mGET /static/images/loading.gif HTTP/1.1[0m" 304 -
> 127.0.0.1 - - [12/Jun/2018 20:09:46] "[36mGET /static/img/glyphicons-halflings.png HTTP/1.1[0m" 304 -
> 127.0.0.1 - - [12/Jun/2018 20:09:46] "[36mGET /static/images/bar.png HTTP/1.1[0m" 304 -
> 127.0.0.1 - - [12/Jun/2018 20:13:46] "[1m[35mGET /monitoring/1/ HTTP/1.1[0m" 500 -
> Traceback (most recent call last):
>   File "/usr/local/lib/python2.7/dist-packages/flask/app.py", line 1997, in __call__
>     return self.wsgi_app(environ, start_response)
>   File "/usr/local/lib/python2.7/dist-packages/flask/app.py", line 1985, in wsgi_app
>     response = self.handle_exception(e)
>   File "/usr/local/lib/python2.7/dist-packages/flask/app.py", line 1540, in handle_exception
>     reraise(exc_type, exc_value, tb)
>   File "/usr/local/lib/python2.7/dist-packages/flask/app.py", line 1982, in wsgi_app
>     response = self.full_dispatch_request()
>   File "/usr/local/lib/python2.7/dist-packages/flask/app.py", line 1614, in full_dispatch_request
>     rv = self.handle_user_exception(e)
>   File "/usr/local/lib/python2.7/dist-packages/flask/app.py", line 1517, in handle_user_exception
>     reraise(exc_type, exc_value, tb)
>   File "/usr/local/lib/python2.7/dist-packages/flask/app.py", line 1612, in full_dispatch_request
>     rv = self.dispatch_request()
>   File "/usr/local/lib/python2.7/dist-packages/flask/app.py", line 1598, in dispatch_request
>     return self.view_functions[rule.endpoint](**req.view_args)
>   File "/usr/local/lib/python2.7/dist-packages/flask_login/utils.py", line 261, in decorated_view
>     return func(*args, **kwargs)
>   File "/home/annemirasol/remidiv2/serveus/views.py", line 63, in returned
>     return function(*args, **kwargs)
>   File "/home/annemirasol/remidiv2/serveus/views.py", line 346, in monitoring
>     for i in unique_coor:
>   File "/usr/local/lib/python2.7/dist-packages/sqlalchemy/orm/loading.py", line 98, in instances
>     util.raise_from_cause(err)
>   File "/usr/local/lib/python2.7/dist-packages/sqlalchemy/util/compat.py", line 203, in raise_from_cause
>     reraise(type(exception), exception, tb=exc_tb, cause=cause)
>   File "/usr/local/lib/python2.7/dist-packages/sqlalchemy/orm/loading.py", line 79, in instances
>     rows = [proc(row) for row in fetch]
>   File "/usr/local/lib/python2.7/dist-packages/sqlalchemy/orm/loading.py", line 493, in _instance
>     loaded_instance, populate_existing, populators)
>   File "/usr/local/lib/python2.7/dist-packages/sqlalchemy/orm/loading.py", line 593, in _populate_full
>     dict_[key] = getter(row)
> ValueError: Couldn't parse datetime string: u'2017-12-01'
> 127.0.0.1 - - [12/Jun/2018 20:13:46] "[37mGET /monitoring/1/?__debugger__=yes&cmd=resource&f=style.css HTTP/1.1[0m" 200 -
> 127.0.0.1 - - [12/Jun/2018 20:13:46] "[37mGET /monitoring/1/?__debugger__=yes&cmd=resource&f=jquery.js HTTP/1.1[0m" 200 -
> 127.0.0.1 - - [12/Jun/2018 20:13:46] "[37mGET /monitoring/1/?__debugger__=yes&cmd=resource&f=debugger.js HTTP/1.1[0m" 200 -
> 127.0.0.1 - - [12/Jun/2018 20:13:46] "[37mGET /monitoring/1/?__debugger__=yes&cmd=resource&f=console.png HTTP/1.1[0m" 200 -
> 127.0.0.1 - - [12/Jun/2018 20:13:46] "[37mGET /monitoring/1/?__debugger__=yes&cmd=resource&f=console.png HTTP/1.1[0m" 200 -
> 127.0.0.1 - - [12/Jun/2018 20:14:47] "[1m[35mGET /monitoring/1/ HTTP/1.1[0m" 500 -
> Traceback (most recent call last):
>   File "/usr/local/lib/python2.7/dist-packages/flask/app.py", line 1997, in __call__
>     return self.wsgi_app(environ, start_response)
>   File "/usr/local/lib/python2.7/dist-packages/flask/app.py", line 1985, in wsgi_app
>     response = self.handle_exception(e)
>   File "/usr/local/lib/python2.7/dist-packages/flask/app.py", line 1540, in handle_exception
>     reraise(exc_type, exc_value, tb)
>   File "/usr/local/lib/python2.7/dist-packages/flask/app.py", line 1982, in wsgi_app
>     response = self.full_dispatch_request()
>   File "/usr/local/lib/python2.7/dist-packages/flask/app.py", line 1614, in full_dispatch_request
>     rv = self.handle_user_exception(e)
>   File "/usr/local/lib/python2.7/dist-packages/flask/app.py", line 1517, in handle_user_exception
>     reraise(exc_type, exc_value, tb)
>   File "/usr/local/lib/python2.7/dist-packages/flask/app.py", line 1612, in full_dispatch_request
>     rv = self.dispatch_request()
>   File "/usr/local/lib/python2.7/dist-packages/flask/app.py", line 1598, in dispatch_request
>     return self.view_functions[rule.endpoint](**req.view_args)
>   File "/usr/local/lib/python2.7/dist-packages/flask_login/utils.py", line 261, in decorated_view
>     return func(*args, **kwargs)
>   File "/home/annemirasol/remidiv2/serveus/views.py", line 63, in returned
>     return function(*args, **kwargs)
>   File "/home/annemirasol/remidiv2/serveus/views.py", line 346, in monitoring
>     for i in unique_coor:
>   File "/usr/local/lib/python2.7/dist-packages/sqlalchemy/orm/loading.py", line 98, in instances
>     util.raise_from_cause(err)
>   File "/usr/local/lib/python2.7/dist-packages/sqlalchemy/util/compat.py", line 203, in raise_from_cause
>     reraise(type(exception), exception, tb=exc_tb, cause=cause)
>   File "/usr/local/lib/python2.7/dist-packages/sqlalchemy/orm/loading.py", line 79, in instances
>     rows = [proc(row) for row in fetch]
>   File "/usr/local/lib/python2.7/dist-packages/sqlalchemy/orm/loading.py", line 493, in _instance
>     loaded_instance, populate_existing, populators)
>   File "/usr/local/lib/python2.7/dist-packages/sqlalchemy/orm/loading.py", line 593, in _populate_full
>     dict_[key] = getter(row)
> ValueError: Couldn't parse datetime string: u'12/01/2017'
> 127.0.0.1 - - [12/Jun/2018 20:14:47] "[37mGET /monitoring/1/?__debugger__=yes&cmd=resource&f=style.css HTTP/1.1[0m" 200 -
> 127.0.0.1 - - [12/Jun/2018 20:14:47] "[37mGET /monitoring/1/?__debugger__=yes&cmd=resource&f=jquery.js HTTP/1.1[0m" 200 -
> 127.0.0.1 - - [12/Jun/2018 20:14:47] "[37mGET /monitoring/1/?__debugger__=yes&cmd=resource&f=debugger.js HTTP/1.1[0m" 200 -
> 127.0.0.1 - - [12/Jun/2018 20:14:47] "[37mGET /monitoring/1/?__debugger__=yes&cmd=resource&f=console.png HTTP/1.1[0m" 200 -
> 127.0.0.1 - - [12/Jun/2018 20:14:47] "[37mGET /monitoring/1/?__debugger__=yes&cmd=resource&f=console.png HTTP/1.1[0m" 200 -
> 127.0.0.1 - - [12/Jun/2018 20:14:47] "[33mGET /favicon.ico HTTP/1.1[0m" 404 -
> 127.0.0.1 - - [12/Jun/2018 20:16:00] "[1m[35mGET /monitoring/1/ HTTP/1.1[0m" 500 -
> Traceback (most recent call last):
>   File "/usr/local/lib/python2.7/dist-packages/flask/app.py", line 1997, in __call__
>     return self.wsgi_app(environ, start_response)
>   File "/usr/local/lib/python2.7/dist-packages/flask/app.py", line 1985, in wsgi_app
>     response = self.handle_exception(e)
>   File "/usr/local/lib/python2.7/dist-packages/flask/app.py", line 1540, in handle_exception
>     reraise(exc_type, exc_value, tb)
>   File "/usr/local/lib/python2.7/dist-packages/flask/app.py", line 1982, in wsgi_app
>     response = self.full_dispatch_request()
>   File "/usr/local/lib/python2.7/dist-packages/flask/app.py", line 1614, in full_dispatch_request
>     rv = self.handle_user_exception(e)
>   File "/usr/local/lib/python2.7/dist-packages/flask/app.py", line 1517, in handle_user_exception
>     reraise(exc_type, exc_value, tb)
>   File "/usr/local/lib/python2.7/dist-packages/flask/app.py", line 1612, in full_dispatch_request
>     rv = self.dispatch_request()
>   File "/usr/local/lib/python2.7/dist-packages/flask/app.py", line 1598, in dispatch_request
>     return self.view_functions[rule.endpoint](**req.view_args)
>   File "/usr/local/lib/python2.7/dist-packages/flask_login/utils.py", line 261, in decorated_view
>     return func(*args, **kwargs)
>   File "/home/annemirasol/remidiv2/serveus/views.py", line 63, in returned
>     return function(*args, **kwargs)
>   File "/home/annemirasol/remidiv2/serveus/views.py", line 346, in monitoring
>     for i in unique_coor:
>   File "/usr/local/lib/python2.7/dist-packages/sqlalchemy/orm/loading.py", line 98, in instances
>     util.raise_from_cause(err)
>   File "/usr/local/lib/python2.7/dist-packages/sqlalchemy/util/compat.py", line 203, in raise_from_cause
>     reraise(type(exception), exception, tb=exc_tb, cause=cause)
>   File "/usr/local/lib/python2.7/dist-packages/sqlalchemy/orm/loading.py", line 79, in instances
>     rows = [proc(row) for row in fetch]
>   File "/usr/local/lib/python2.7/dist-packages/sqlalchemy/orm/loading.py", line 493, in _instance
>     loaded_instance, populate_existing, populators)
>   File "/usr/local/lib/python2.7/dist-packages/sqlalchemy/orm/loading.py", line 593, in _populate_full
>     dict_[key] = getter(row)
> ValueError: Couldn't parse datetime string: u'12/01/2017 01:00:00'
> 127.0.0.1 - - [12/Jun/2018 20:16:00] "[37mGET /monitoring/1/?__debugger__=yes&cmd=resource&f=style.css HTTP/1.1[0m" 200 -
> 127.0.0.1 - - [12/Jun/2018 20:16:00] "[37mGET /monitoring/1/?__debugger__=yes&cmd=resource&f=jquery.js HTTP/1.1[0m" 200 -
> 127.0.0.1 - - [12/Jun/2018 20:16:00] "[37mGET /monitoring/1/?__debugger__=yes&cmd=resource&f=debugger.js HTTP/1.1[0m" 200 -
> 127.0.0.1 - - [12/Jun/2018 20:16:00] "[37mGET /monitoring/1/?__debugger__=yes&cmd=resource&f=console.png HTTP/1.1[0m" 200 -
> 127.0.0.1 - - [12/Jun/2018 20:16:00] "[37mGET /monitoring/1/?__debugger__=yes&cmd=resource&f=console.png HTTP/1.1[0m" 200 -
> 127.0.0.1 - - [12/Jun/2018 20:17:42] "[37mGET /monitoring/1/ HTTP/1.1[0m" 200 -
> 127.0.0.1 - - [12/Jun/2018 20:17:42] "[36mGET /static/css/bootstrap.min.css HTTP/1.1[0m" 304 -
> 127.0.0.1 - - [12/Jun/2018 20:17:42] "[36mGET /static/css/bootstrap-responsive.css HTTP/1.1[0m" 304 -
> 127.0.0.1 - - [12/Jun/2018 20:17:42] "[36mGET /static/js/eyecon-datepicker.js HTTP/1.1[0m" 304 -
> 127.0.0.1 - - [12/Jun/2018 20:17:42] "[36mGET /static/js/bootstrap.min.js HTTP/1.1[0m" 304 -
> 127.0.0.1 - - [12/Jun/2018 20:17:42] "[36mGET /static/js/jquery.js HTTP/1.1[0m" 304 -
> 127.0.0.1 - - [12/Jun/2018 20:17:42] "[36mGET /static/css/eyecon-datepicker.css HTTP/1.1[0m" 304 -
> 127.0.0.1 - - [12/Jun/2018 20:17:42] "[36mGET /static/images/loading.gif HTTP/1.1[0m" 304 -
> 127.0.0.1 - - [12/Jun/2018 20:17:42] "[36mGET /static/img/glyphicons-halflings.png HTTP/1.1[0m" 304 -
> 127.0.0.1 - - [12/Jun/2018 20:17:42] "[37mGET /static/images/bar.png HTTP/1.1[0m" 200 -
> 127.0.0.1 - - [12/Jun/2018 20:17:54] "[37mGET /records/1 HTTP/1.1[0m" 200 -
> 127.0.0.1 - - [12/Jun/2018 20:17:54] "[37mGET /static/css/bootstrap-responsive.css HTTP/1.1[0m" 200 -
> Error on request:
Traceback (most recent call last):
  File "/usr/local/lib/python2.7/dist-packages/werkzeug/serving.py", line 270, in run_wsgi
    execute(self.server.app)
  File "/usr/local/lib/python2.7/dist-packages/werkzeug/serving.py", line 261, in execute
    write(data)
  File "/usr/local/lib/python2.7/dist-packages/werkzeug/serving.py", line 227, in write
    self.send_header(key, value)
  File "/usr/lib/python2.7/BaseHTTPServer.py", line 412, in send_header
    self.wfile.write("%s: %s\r\n" % (keyword, value))
IOError: [Errno 32] Broken pipe
> 127.0.0.1 - - [12/Jun/2018 20:18:25] "[37mGET /case/1/ HTTP/1.1[0m" 200 -
> 127.0.0.1 - - [12/Jun/2018 20:19:52] "[37mGET /case/1/ HTTP/1.1[0m" 200 -
> 127.0.0.1 - - [12/Jun/2018 20:19:52] "[36mGET /static/css/bootstrap.min.css HTTP/1.1[0m" 304 -
> 127.0.0.1 - - [12/Jun/2018 20:19:52] "[36mGET /static/css/bootstrap-responsive.css HTTP/1.1[0m" 304 -
> 127.0.0.1 - - [12/Jun/2018 20:19:52] "[36mGET /static/css/eyecon-datepicker.css HTTP/1.1[0m" 304 -
> 127.0.0.1 - - [12/Jun/2018 20:19:52] "[36mGET /static/js/jquery.js HTTP/1.1[0m" 304 -
> 127.0.0.1 - - [12/Jun/2018 20:19:52] "[36mGET /static/js/bootstrap.min.js HTTP/1.1[0m" 304 -
> 127.0.0.1 - - [12/Jun/2018 20:19:52] "[36mGET /static/img/glyphicons-halflings.png HTTP/1.1[0m" 304 -
> 127.0.0.1 - - [12/Jun/2018 20:19:54] "[37mGET /case/1/ HTTP/1.1[0m" 200 -
> 127.0.0.1 - - [12/Jun/2018 20:19:54] "[36mGET /static/css/bootstrap.min.css HTTP/1.1[0m" 304 -
> 127.0.0.1 - - [12/Jun/2018 20:19:54] "[36mGET /static/css/bootstrap-responsive.css HTTP/1.1[0m" 304 -
> 127.0.0.1 - - [12/Jun/2018 20:19:54] "[36mGET /static/css/eyecon-datepicker.css HTTP/1.1[0m" 304 -
> 127.0.0.1 - - [12/Jun/2018 20:19:54] "[36mGET /static/js/jquery.js HTTP/1.1[0m" 304 -
> 127.0.0.1 - - [12/Jun/2018 20:19:54] "[36mGET /static/js/bootstrap.min.js HTTP/1.1[0m" 304 -
> 127.0.0.1 - - [12/Jun/2018 20:19:54] "[36mGET /static/img/glyphicons-halflings.png HTTP/1.1[0m" 304 -
> 127.0.0.1 - - [12/Jun/2018 20:20:07] "[37mGET /monitoring/1/ HTTP/1.1[0m" 200 -
> 127.0.0.1 - - [12/Jun/2018 20:20:08] "[37mGET /static/images/loading.gif HTTP/1.1[0m" 200 -
> Error on request:
Traceback (most recent call last):
  File "/usr/local/lib/python2.7/dist-packages/werkzeug/serving.py", line 270, in run_wsgi
    execute(self.server.app)
  File "/usr/local/lib/python2.7/dist-packages/werkzeug/serving.py", line 261, in execute
    write(data)
  File "/usr/local/lib/python2.7/dist-packages/werkzeug/serving.py", line 227, in write
    self.send_header(key, value)
  File "/usr/lib/python2.7/BaseHTTPServer.py", line 412, in send_header
    self.wfile.write("%s: %s\r\n" % (keyword, value))
IOError: [Errno 32] Broken pipe
> 127.0.0.1 - - [12/Jun/2018 20:20:24] "[37mGET /map/1 HTTP/1.1[0m" 200 -
> 127.0.0.1 - - [12/Jun/2018 20:20:24] "[36mGET /static/js/markerwithlabel.js HTTP/1.1[0m" 304 -
> 127.0.0.1 - - [12/Jun/2018 20:20:50] "[37mGET /map/1 HTTP/1.1[0m" 200 -
> 127.0.0.1 - - [12/Jun/2018 20:20:50] "[36mGET /static/css/bootstrap.min.css HTTP/1.1[0m" 304 -
> 127.0.0.1 - - [12/Jun/2018 20:20:50] "[36mGET /static/css/bootstrap-responsive.css HTTP/1.1[0m" 304 -
> 127.0.0.1 - - [12/Jun/2018 20:20:50] "[36mGET /static/js/jquery.js HTTP/1.1[0m" 304 -
> 127.0.0.1 - - [12/Jun/2018 20:20:50] "[36mGET /static/css/eyecon-datepicker.css HTTP/1.1[0m" 304 -
> 127.0.0.1 - - [12/Jun/2018 20:20:50] "[36mGET /static/js/bootstrap.min.js HTTP/1.1[0m" 304 -
> 127.0.0.1 - - [12/Jun/2018 20:20:50] "[36mGET /static/js/eyecon-datepicker.js HTTP/1.1[0m" 304 -
> 127.0.0.1 - - [12/Jun/2018 20:20:50] "[37mGET /static/js/markerwithlabel.js HTTP/1.1[0m" 200 -
> 127.0.0.1 - - [12/Jun/2018 20:20:50] "[36mGET /static/images/loading.gif HTTP/1.1[0m" 304 -
> 127.0.0.1 - - [12/Jun/2018 20:20:50] "[36mGET /static/img/glyphicons-halflings.png HTTP/1.1[0m" 304 -
> 127.0.0.1 - - [12/Jun/2018 20:20:59] "[32mGET /case/1 HTTP/1.1[0m" 301 -
> 127.0.0.1 - - [12/Jun/2018 20:20:59] "[37mGET /case/1/ HTTP/1.1[0m" 200 -
> 127.0.0.1 - - [12/Jun/2018 20:20:59] "[37mGET /static/img/glyphicons-halflings.png HTTP/1.1[0m" 200 -
> Error on request:
Traceback (most recent call last):
  File "/usr/local/lib/python2.7/dist-packages/werkzeug/serving.py", line 270, in run_wsgi
    execute(self.server.app)
  File "/usr/local/lib/python2.7/dist-packages/werkzeug/serving.py", line 261, in execute
    write(data)
  File "/usr/local/lib/python2.7/dist-packages/werkzeug/serving.py", line 227, in write
    self.send_header(key, value)
  File "/usr/lib/python2.7/BaseHTTPServer.py", line 412, in send_header
    self.wfile.write("%s: %s\r\n" % (keyword, value))
IOError: [Errno 32] Broken pipe
> 127.0.0.1 - - [12/Jun/2018 20:21:06] "[37mGET /monitoring/1/ HTTP/1.1[0m" 200 -
> 127.0.0.1 - - [12/Jun/2018 20:21:44] "[37mGET /monitoring/1/ HTTP/1.1[0m" 200 -
> 127.0.0.1 - - [12/Jun/2018 20:21:44] "[36mGET /static/css/bootstrap.min.css HTTP/1.1[0m" 304 -
> 127.0.0.1 - - [12/Jun/2018 20:21:44] "[36mGET /static/css/bootstrap-responsive.css HTTP/1.1[0m" 304 -
> 127.0.0.1 - - [12/Jun/2018 20:21:44] "[36mGET /static/css/eyecon-datepicker.css HTTP/1.1[0m" 304 -
> 127.0.0.1 - - [12/Jun/2018 20:21:44] "[36mGET /static/js/jquery.js HTTP/1.1[0m" 304 -
> 127.0.0.1 - - [12/Jun/2018 20:21:44] "[36mGET /static/js/bootstrap.min.js HTTP/1.1[0m" 304 -
> 127.0.0.1 - - [12/Jun/2018 20:21:44] "[36mGET /static/js/eyecon-datepicker.js HTTP/1.1[0m" 304 -
> 127.0.0.1 - - [12/Jun/2018 20:21:44] "[36mGET /static/images/loading.gif HTTP/1.1[0m" 304 -
> 127.0.0.1 - - [12/Jun/2018 20:21:44] "[36mGET /static/img/glyphicons-halflings.png HTTP/1.1[0m" 304 -
> 127.0.0.1 - - [12/Jun/2018 20:21:44] "[36mGET /static/images/bar.png HTTP/1.1[0m" 304 -
> 127.0.0.1 - - [12/Jun/2018 20:21:54] "[37mGET /map/1 HTTP/1.1[0m" 200 -
> 127.0.0.1 - - [12/Jun/2018 20:21:54] "[37mGET /static/images/loading.gif HTTP/1.1[0m" 200 -
> Error on request:
Traceback (most recent call last):
  File "/usr/local/lib/python2.7/dist-packages/werkzeug/serving.py", line 270, in run_wsgi
    execute(self.server.app)
  File "/usr/local/lib/python2.7/dist-packages/werkzeug/serving.py", line 261, in execute
    write(data)
  File "/usr/local/lib/python2.7/dist-packages/werkzeug/serving.py", line 227, in write
    self.send_header(key, value)
  File "/usr/lib/python2.7/BaseHTTPServer.py", line 412, in send_header
    self.wfile.write("%s: %s\r\n" % (keyword, value))
IOError: [Errno 32] Broken pipe
> 127.0.0.1 - - [12/Jun/2018 20:21:54] "[37mGET /static/img/glyphicons-halflings.png HTTP/1.1[0m" 200 -
> 127.0.0.1 - - [12/Jun/2018 20:22:04] "[37mGET /monitoring/1/ HTTP/1.1[0m" 200 -
